- [1. Что такое исключение? Для чего они нужны? ](#1-что-такое-исключение-для-чего-они-нужны)
- [2. Расскажи про иерархию исключений?](#2-расскажи-про-иерархию-исключений-)
- [3. В чём разница между проверяемыми исключениями и непроверяемыми? В чём разница с точки зрения синтаксиса и идеологическая при использовании?](#3-в-чём-разница-между-проверяемыми-исключениями-и-непроверяемыми-в-чём-разница-с-точки-зрения-синтаксиса-и-идеологическая-при-использовании)
- [4. Можно ли обработать непроверяемое исключение?](#4-можно-ли-обработать-непроверяемое-исключение)
- [5. Нужно ли ловить Error исключения?](#5-нужно-ли-ловить-error-исключения)
- [6. Как бросить исключение? Можно ли бросить НЕ новое исключение? ](#6-как-бросить-исключение-можно-ли-бросить-не-новое-исключение)
- [7. Расскажи про информацию, которая находится внутри исключения? Как с ней работать?](#7-расскажи-про-информацию-которая-находится-внутри-исключения-как-с-ней-работать)
- [8. Что такое подавленные исключения? Как достать подавленное исключение?](#8-что-такое-подавленные-исключения-как-достать-подавленное-исключение)
- [9. Какую информацию можно получить из StackTraceElement?](#9-какую-информацию-можно-получить-из-stacktraceelement)
- [10. Расскажи про конструкцию try-catch-finally?](#10-расскажи-про-конструкцию-try-catch-finally)
- [11. Что такое try-with-resources? Как работает эта конструкция?](#11-что-такое-try-with-resources-как-работает-эта-конструкция)
- [12. Расскажи, как правильно ловить исключения? Иерархия catch блоков](#12-расскажи-как-правильно-ловить-исключения-иерархия-catch-блоков)
- [13. Можно ли в одном catch обработать несколько исключений?](#13-можно-ли-в-одном-catch-обработать-несколько-исключений)


## 1. Что такое исключение? Для чего они нужны?


**Исключения** — это механизм обработки ошибок в программировании. Они позволяют программе реагировать на непредвиденные ситуации или ошибки, которые могут возникнуть во время её работы.

### Основные моменты:

1.  **Что такое исключение?** Исключение — это событие, которое прерывает нормальное выполнение программы. Оно возникает, когда программа сталкивается с ошибкой (например, деление на ноль, обращение к несуществующему элементу массива, отсутствие файла), и требует специальной обработки.
    
2.  **Зачем они нужны?** Исключения позволяют:
    
    *   **Изолировать код обработки ошибок**: Вместо того, чтобы проверять ошибки в каждой строке кода, можно использовать блоки `try-catch`, которые будут автоматически перехватывать и обрабатывать ошибки.
    *   **Повышение читаемости кода**: Код становится чище и понятнее, так как исключения не нужно обрабатывать вручную после каждой потенциальной ошибки.
    *   **Гибкость**: Можно создавать собственные исключения для специфических ошибок в программе и обрабатывать их по-разному.

### Пример (на Java):

```java
try {
    int result = 10 / 0; // Деление на ноль
} catch (ArithmeticException e) {
    System.out.println("Ошибка: попытка деления на ноль!");
} finally {
    System.out.println("Этот блок выполнится в любом случае.");
}
```

В данном примере ошибка деления на ноль будет перехвачена и обработана блоком `catch`. Блок `finally` всегда выполнится, независимо от того, произошло ли исключение или нет.

### Важные аспекты:

*   **try**: Блок, в котором может произойти ошибка.
*   **catch**: Блок для перехвата и обработки ошибки.
*   **finally**: Блок, который выполняется в любом случае, даже если исключение не произошло.

Исключения — важная часть разработки, особенно при создании надежных и устойчивых приложений.

## 2. Расскажи про иерархию исключений?


В Java все исключения имеют общую базовую суперкласс `Throwable`. Это родительский класс для двух основных типов: **исключений** (`Exception`) и **ошибок** (`Error`). Эти два класса и их подклассы образуют иерархию исключений.

Вот как выглядит иерархия:

```
Throwable
├── Error
└── Exception
    ├── RuntimeException
    └── Проверяемые исключения (Checked Exceptions)
```

### 1\. **Throwable**

`Throwable` — это корневой класс для всех исключений и ошибок. Он делится на две категории:

*   **Error**: Ошибки, которые обычно связаны с проблемами в самой виртуальной машине Java (JVM). Они обычно не поддаются обработке, и программа не должна пытаться их перехватывать.
*   **Exception**: Исключения, которые происходят из-за ошибок в логике программы или внешних факторов, и с которыми можно работать, обрабатывая их в коде.

### 2\. **Error**

Класс `Error` и его подклассы представляют серьезные проблемы, которые нельзя обработать с помощью обычных исключений. Примеры:

*   **OutOfMemoryError** — нехватка памяти.
*   **StackOverflowError** — переполнение стека (чаще всего из-за рекурсии).
*   **VirtualMachineError** — ошибки виртуальной машины Java.

Ошибки, как правило, не должны перехватываться, потому что они обычно указывают на непоправимые проблемы в системе.

### 3\. **Exception**

`Exception` — это класс, который используется для всех исключений, которые могут возникать в программе. Его подклассы делятся на две категории:

#### a. **Проверяемые исключения (Checked Exceptions)**

Это исключения, которые проверяются во время компиляции. Программа обязана обрабатывать такие исключения либо с помощью блока `try-catch`, либо с помощью ключевого слова `throws`. Примеры:

*   **IOException** — ошибка ввода-вывода (например, при чтении файла).
*   **SQLException** — ошибка при работе с базой данных.
*   **ClassNotFoundException** — класс не найден.

Если код вызывает метод, который может выбросить проверяемое исключение, то компилятор требует обработки этого исключения.

#### b. **Непроверяемые исключения (Unchecked Exceptions)**

Это исключения, которые наследуются от `RuntimeException` и не проверяются компилятором. Их можно перехватывать, но это не обязательно. Примеры:

*   **NullPointerException** — попытка работы с объектом, который равен `null`.
*   **ArrayIndexOutOfBoundsException** — попытка обратиться к элементу массива по недопустимому индексу.
*   **ArithmeticException** — ошибка арифметических операций (например, деление на ноль).
*   **IllegalArgumentException** — передача недопустимого аргумента методу.

Эти исключения обычно происходят из-за ошибок в логике программы, и их обычно не перехватывают, так как такие ошибки нужно исправлять на этапе разработки.

### Пример иерархии:

```java
// Проверяемое исключение
try {
    throw new IOException("Ошибка при чтении файла");
} catch (IOException e) {
    System.out.println("Поймано проверяемое исключение: " + e.getMessage());
}

// Непроверяемое исключение
try {
    throw new ArithmeticException("Ошибка в арифметике");
} catch (ArithmeticException e) {
    System.out.println("Поймано непроверяемое исключение: " + e.getMessage());
}
```

### Основные моменты:

*   **Checked Exceptions** (проверяемые) должны быть обработаны в коде или объявлены с помощью `throws`.
*   **Unchecked Exceptions** (непроверяемые) могут быть выброшены в любой момент, но их обработка не обязательна.

Эта иерархия позволяет удобно управлять ошибками и исключениями в программе, разделяя те, которые могут быть обработаны, и те, которые представляют серьезные сбои в системе.

## 3. В чём разница между проверяемыми исключениями и непроверяемыми? В чём разница с точки зрения синтаксиса и идеологическая при использовании?


Разница между **проверяемыми** и **непроверяемыми исключениями** в Java заключается как в синтаксисе, так и в идеологии их использования.

### 1\. **Проверяемые исключения (Checked Exceptions)**

#### Синтаксис:

*   Когда метод может выбросить проверяемое исключение, это исключение должно быть либо обработано с помощью блока `try-catch`, либо должно быть объявлено в сигнатуре метода с использованием ключевого слова `throws`.
*   Компилятор будет проверять, обработали ли вы это исключение, и если нет — выдаст ошибку компиляции.

**Пример**:

```java
// Метод, который выбрасывает проверяемое исключение
public void readFile() throws IOException {
    FileReader file = new FileReader("file.txt");
    BufferedReader reader = new BufferedReader(file);
    // Ожидается, что IOException будет обработано
}

// Код, который вызывает этот метод
public void someMethod() {
    try {
        readFile();
    } catch (IOException e) {
        e.printStackTrace();
    }
}
```

#### Идеология:

*   **Checked Exceptions** представляют ошибки, которые можно предсказать и с которыми программа может столкнуться в обычной работе (например, проблемы с сетью, файлами, базами данных).
*   Если метод работает с такими ресурсами, как файлы или базы данных, то эти исключения должны быть учтены и обработаны, потому что они требуют внимания от разработчика, чтобы гарантировать корректную работу программы.
*   Они "принуждают" разработчика к обработке возможных ошибок, что способствует более безопасному коду.

### 2\. **Непроверяемые исключения (Unchecked Exceptions)**

#### Синтаксис:

*   Непроверяемые исключения — это исключения, наследующие от `RuntimeException` (например, `NullPointerException`, `ArrayIndexOutOfBoundsException`, и другие).
*   Эти исключения не требуют обязательной обработки с помощью `try-catch` или декларации с `throws` в сигнатуре метода. Компилятор не заставляет разработчика их обрабатывать.
*   Можно выкидывать и не обрабатывать их без ошибок компиляции.

**Пример**:

```java
// Метод, который может выбросить непроверяемое исключение
public void divideByZero() {
    int result = 10 / 0; // Генерирует ArithmeticException
}

// Код, который вызывает этот метод
public void someMethod() {
    divideByZero(); // Не обязательно обрабатывать
}
```

#### Идеология:

*   **Unchecked Exceptions** часто представляют ошибки программирования, такие как ошибки в логике (например, деление на ноль или обращение к `null`), которые обычно свидетельствуют о дефектах в коде, которые нужно исправить на этапе разработки.
*   Их использование предполагает, что программист будет избегать их появления, исправляя код до того, как они произойдут.
*   Это позволяет не перегружать код лишними обработками, если ошибки считаются результатом неправильного использования API или ошибок в логике программы.

### 3\. **Разница в подходах и философии:**

#### Проверяемые исключения:

*   Предполагают, что ошибки могут быть предсказуемыми и с ними можно и нужно работать.
*   Они вынуждают разработчика задуматься о возможных проблемах и проработать их в коде, что делает программу более надежной.
*   Это полезно, когда вы работаете с внешними ресурсами (файлы, сеть и т. п.), где ошибки могут быть предсказуемыми и требующими особой обработки.

#### Непроверяемые исключения:

*   Предполагают, что ошибки в основном происходят из-за проблем в коде (например, неверное использование API, ошибки программирования).
*   Такие исключения не должны быть обязательно обработаны, потому что они часто указывают на ошибки, которые нужно исправить на этапе разработки.
*   Это позволяет делать код более компактным и менее перегруженным, однако, увеличивает вероятность возникновения ошибок в случае неправильного использования методов.

### 4\. **Заключение:**

*   **Проверяемые исключения** следует использовать, когда ошибка может быть предсказана и требует обработки (например, ошибки ввода-вывода, проблемы с подключением к базе данных).
*   **Непроверяемые исключения** применяются для ошибок программирования, которые не могут быть обработаны на уровне метода (например, ошибки логики), и их желательно исправлять на этапе разработки.

Таким образом, выбор между этими типами исключений зависит от того, насколько ошибка предсказуема и как с ней следует работать в контексте программы.

## 4. Можно ли обработать непроверяемое исключение?


Да, **непроверяемое исключение** (например, наследующее от `RuntimeException`) можно обработать, но **это не обязательно**. В отличие от проверяемых исключений, для которых компилятор требует обязательной обработки, непроверяемые исключения могут быть обработаны по усмотрению разработчика.

### Пример обработки непроверяемого исключения:

```java
public class UncheckedExceptionExample {
    public static void main(String[] args) {
        try {
            // Генерация непроверяемого исключения
            int[] arr = new int[2];
            System.out.println(arr[5]); // Это вызовет ArrayIndexOutOfBoundsException
        } catch (ArrayIndexOutOfBoundsException e) {
            System.out.println("Обработано исключение: " + e.getMessage());
        }
    }
}
```

В этом примере происходит попытка доступа к элементу массива по индексу, который выходит за пределы массива, что приводит к `ArrayIndexOutOfBoundsException`. Это непроверяемое исключение было перехвачено и обработано в блоке `catch`.

### Когда стоит обрабатывать непроверяемое исключение?

*   Если исключение действительно является результатом ошибки, которую можно восстановить или обработать (например, выход за границы массива), то можно использовать обработку.
*   Например, если вы уверены, что некоторые исключения могут быть "нормальными" в контексте вашего приложения (например, попытка обратиться к несуществующему элементу массива в некоторых случаях), вы можете обработать их, чтобы программа продолжала работать.

### Когда не стоит обрабатывать непроверяемое исключение?

*   Непроверяемые исключения часто указывают на ошибки программирования (например, `NullPointerException` или `ArithmeticException`), которые должны быть исправлены на этапе разработки.
*   В большинстве случаев, если вы сталкиваетесь с непроверяемым исключением, это сигнализирует о том, что есть ошибка в логике программы, и вместо того чтобы её "прикрывать" с помощью обработки исключений, лучше исправить проблему в коде.

### Итог:

*   **Да**, непроверяемые исключения можно обработать, но это не обязательно. В идеале они должны быть избегаемы путём исправления ошибок в логике программы.


## 5. Нужно ли ловить Error исключения?


В большинстве случаев **ловить исключения типа `Error` не рекомендуется**, так как они представляют критические ошибки, связанные с работой JVM или системными сбоями, которые программа **не может и не должна** обрабатывать.

### ❌ **Почему не стоит ловить `Error`?**

1.  **Они связаны с критическими сбоями**, такими как:
    
    *   `OutOfMemoryError` – нехватка памяти.
    *   `StackOverflowError` – переполнение стека (обычно из-за бесконечной рекурсии).
    *   `VirtualMachineError` – ошибки работы JVM.
2.  **Обработка `Error` не решает проблему**, а только скрывает её, что может привести к нестабильной работе приложения.
    
3.  **Ловля `Error` может мешать нормальному завершению программы**. Например, если JVM уже не может выделить память (`OutOfMemoryError`), перехват такого исключения не освободит ресурсы, а только отложит неизбежное падение.
    

* * *

### ✅ **Когда можно ловить `Error`?**

Хотя в большинстве случаев ловить `Error` не нужно, бывают исключения:

*   **Если приложение должно сделать логирование перед аварийным завершением**:
    
    ```java
    try {
        int[] arr = new int[Integer.MAX_VALUE]; // Вызовет OutOfMemoryError
    } catch (OutOfMemoryError e) {
        System.err.println("Критическая ошибка: " + e.getMessage());
        // Можно сохранить логи перед завершением работы
    }
    ```
    
*   **Если приложение должно завершиться корректно (например, сервер), освобождая ресурсы**:
    
    ```java
    try {
        recursiveMethod();
    } catch (StackOverflowError e) {
        System.err.println("Рекурсия зашла слишком далеко. Попробуйте другой алгоритм.");
    }
    ```
    
*   **Если нужна защита от краха отдельных потоков в многопоточной среде**:
    *   В этом случае `Error` можно перехватывать на уровне `Thread.setUncaughtExceptionHandler`.

* * *

### ⚠ **Вывод**:

*   В **99% случаев `Error` ловить не нужно** – это проблемы JVM, которые невозможно корректно обработать.
*   Единственные случаи, когда это может быть оправдано – **логирование перед завершением работы или защита от краха потоков**.
*   Для большинства ошибок программы нужно ловить **исключения (`Exception`), а не ошибки (`Error`)**.

## 6. Как бросить исключение? Можно ли бросить НЕ новое исключение?


### **Как бросить исключение в Java?**

В Java для выбрасывания исключения используется ключевое слово `throw`. Исключение должно быть объектом класса, который наследуется от `Throwable` (обычно это `Exception` или `Error`).

**Пример выбрасывания нового исключения:**

```java
public void divide(int a, int b) {
    if (b == 0) {
        throw new ArithmeticException("Деление на ноль запрещено!");
    }
    System.out.println(a / b);
}
```

В этом примере выбрасывается `ArithmeticException`, если `b == 0`.

* * *

### **Можно ли бросить НЕ новое исключение?**

Да, можно. Если у вас есть перехваченное исключение, его можно снова выбросить с помощью `throw`.

**Пример повторного выбрасывания исключения:**

```java
public void readFile() throws IOException {
    try {
        FileReader file = new FileReader("file.txt");
    } catch (IOException e) {
        System.out.println("Ошибка чтения файла: " + e.getMessage());
        throw e; // Повторное выбрасывание исключения
    }
}
```

В этом коде исключение `IOException` сначала обрабатывается (`catch`), но затем снова выбрасывается, чтобы передать его выше по стеку вызовов.

* * *

### **Можно ли бросить то же самое исключение, но с новой информацией?**

Да, можно обернуть старое исключение в новое (`cause`), используя `throw new ...`, передав старое исключение в качестве причины (`Throwable cause`).

**Пример оборачивания исключения:**

```java
public void processFile() throws CustomException {
    try {
        readFile();
    } catch (IOException e) {
        throw new CustomException("Ошибка при обработке файла", e);
    }
}

// Определение собственного исключения
class CustomException extends Exception {
    public CustomException(String message, Throwable cause) {
        super(message, cause);
    }
}
```

Здесь `IOException` оборачивается в `CustomException`, что помогает сохранить исходную информацию об ошибке.

* * *

### **Вывод**

*   **Можно бросить новое исключение** с помощью `throw new`.
*   **Можно повторно выбросить пойманное исключение** с помощью `throw e`.
*   **Можно обернуть одно исключение в другое** (чтобы не терять стек вызовов), передав его в качестве `cause`.

## 7. Расскажи про информацию, которая находится внутри исключения? Как с ней работать?


Когда в Java выбрасывается исключение (объект класса `Throwable`), оно содержит полезную информацию, которая помогает диагностировать проблему. Давай разберём, что внутри исключения и как с этим работать.

* * *

**1\. Какие данные содержит исключение?**
-----------------------------------------

Класс `Throwable` (от которого наследуются `Exception` и `Error`) содержит следующие ключевые методы:

| Метод | Описание |
| --- | --- |
| `getMessage()` | Возвращает строку с описанием ошибки (если передавалась при создании исключения). |
| `getCause()` | Возвращает исключение, которое стало причиной текущего (`cause`). |
| `printStackTrace()` | Выводит стек вызовов в стандартный поток ошибок (`System.err`). |
| `getStackTrace()` | Возвращает массив `StackTraceElement[]`, описывающий стек вызовов. |

* * *

**2\. Пример работы с информацией об исключении**
-------------------------------------------------

### **Простой пример:**

```java
public class ExceptionExample {
    public static void main(String[] args) {
        try {
            int result = 10 / 0; // Вызовет ArithmeticException
        } catch (ArithmeticException e) {
            System.out.println("Сообщение: " + e.getMessage()); // Сообщение об ошибке
            e.printStackTrace(); // Вывод стека вызовов
        }
    }
}
```

**Вывод в консоль:**

```
Сообщение: / by zero
java.lang.ArithmeticException: / by zero
	at ExceptionExample.main(ExceptionExample.java:5)
```

* * *

**3\. Получение информации о стеке вызовов**
--------------------------------------------

### **Использование `getStackTrace()`**

```java
public class StackTraceExample {
    public static void main(String[] args) {
        try {
            throwException();
        } catch (Exception e) {
            System.out.println("Исключение: " + e);
            
            for (StackTraceElement element : e.getStackTrace()) {
                System.out.println("Класс: " + element.getClassName());
                System.out.println("Метод: " + element.getMethodName());
                System.out.println("Файл: " + element.getFileName());
                System.out.println("Строка: " + element.getLineNumber());
                System.out.println("-----");
            }
        }
    }

    public static void throwException() {
        throw new RuntimeException("Ошибка в методе throwException");
    }
}
```

**Пример вывода:**

```
Исключение: java.lang.RuntimeException: Ошибка в методе throwException
Класс: StackTraceExample
Метод: throwException
Файл: StackTraceExample.java
Строка: 17
-----
Класс: StackTraceExample
Метод: main
Файл: StackTraceExample.java
Строка: 6
-----
```

* * *

**4\. Использование `getCause()`**
----------------------------------

Если исключение вызвано другим исключением, можно получить его "корень" с помощью `getCause()`.

### **Пример оборачивания исключения:**

```java
public class CauseExample {
    public static void main(String[] args) {
        try {
            methodA();
        } catch (Exception e) {
            System.out.println("Основное исключение: " + e);
            System.out.println("Причина исключения: " + e.getCause());
        }
    }

    public static void methodA() throws Exception {
        try {
            methodB();
        } catch (NullPointerException e) {
            throw new Exception("Ошибка в methodA", e); // Оборачиваем исключение
        }
    }

    public static void methodB() {
        throw new NullPointerException("Ошибка в methodB");
    }
}
```

**Вывод в консоль:**

```
Основное исключение: java.lang.Exception: Ошибка в methodA
Причина исключения: java.lang.NullPointerException: Ошибка в methodB
```

Здесь `methodA()` выбросил новое исключение `Exception`, но указал в `cause` исходное `NullPointerException`, чтобы сохранить всю информацию о реальной проблеме.

* * *

**5\. Заключение**
------------------

*   **`getMessage()`** – возвращает текст ошибки.
*   **`printStackTrace()`** – выводит стек вызовов в консоль.
*   **`getStackTrace()`** – даёт подробные данные о методах, вызвавших исключение.
*   **`getCause()`** – помогает понять, что вызвало исключение.

Использование этих методов позволяет **анализировать ошибки, логировать их и находить причины сбоев в программе**.

## 8. Что такое подавленные исключения? Как достать подавленное исключение?


### **Подавленные исключения в Java**

Подавленные исключения (**suppressed exceptions**) – это исключения, которые возникают **во время обработки другого исключения**, но не становятся основными. Они появляются, когда используется **try-with-resources** (автоматическое закрытие ресурсов), и исключение выбрасывается при закрытии ресурса.

* * *

### **Как возникают подавленные исключения?**

Когда в `try-with-resources` блоке генерируется исключение, а затем в `close()` ресурса выбрасывается другое исключение, **исключение из `close()` подавляется** и не перезаписывает основное. Однако его можно извлечь.

* * *

### **Пример подавленного исключения**

```java
class Resource implements AutoCloseable {
    @Override
    public void close() throws Exception {
        throw new Exception("Ошибка при закрытии ресурса");
    }
}

public class SuppressedExceptionExample {
    public static void main(String[] args) {
        try (Resource resource = new Resource()) {
            throw new Exception("Основное исключение в блоке try");
        } catch (Exception e) {
            System.out.println("Основное исключение: " + e.getMessage());

            // Достаем подавленные исключения
            for (Throwable suppressed : e.getSuppressed()) {
                System.out.println("Подавленное исключение: " + suppressed.getMessage());
            }
        }
    }
}
```

### **Вывод в консоль:**

```
Основное исключение: Основное исключение в блоке try
Подавленное исключение: Ошибка при закрытии ресурса
```

Здесь основное исключение `"Основное исключение в блоке try"` **не теряется**, а исключение из `close()` подавляется.

* * *

### **Как получить подавленные исключения?**

Метод **`Throwable.getSuppressed()`** возвращает массив `Throwable[]`, содержащий все подавленные исключения.

```java
Throwable[] suppressedExceptions = e.getSuppressed();
for (Throwable suppressed : suppressedExceptions) {
    System.out.println(suppressed.getMessage());
}
```

* * *

### **Как вручную добавить подавленное исключение?**

Иногда нужно **добавить подавленное исключение вручную**, используя `Throwable.addSuppressed()`.

```java
public class AddSuppressedExample {
    public static void main(String[] args) {
        Exception mainException = new Exception("Основное исключение");
        Exception suppressedException = new Exception("Подавленное исключение");

        mainException.addSuppressed(suppressedException);

        System.out.println("Основное исключение: " + mainException.getMessage());
        for (Throwable suppressed : mainException.getSuppressed()) {
            System.out.println("Подавленное исключение: " + suppressed.getMessage());
        }
    }
}
```

**Вывод:**

```
Основное исключение: Основное исключение
Подавленное исключение: Подавленное исключение
```

* * *

### **Когда это полезно?**

*   Логирование всех исключений без потери информации.
*   Разбор ошибок, когда есть основное исключение и дополнительные проблемы с ресурсами.
*   Улучшение отладки, особенно при использовании `try-with-resources`.

* * *

### **Вывод**

*   Подавленные исключения возникают, если в `try-with-resources` ошибка произошла **как в блоке try, так и при закрытии ресурса**.
*   Их можно получить через **`getSuppressed()`** и вручную добавить через **`addSuppressed()`**.
*   Это механизм, который помогает **не терять информацию об ошибках**, если они происходят одновременно.

## 9. Какую информацию можно получить из StackTraceElement?


Класс `StackTraceElement` в Java представляет собой **один элемент стека вызовов**, который содержит информацию о методе, в котором возникло исключение.

* * *

**Какие данные можно получить из `StackTraceElement`?**
-------------------------------------------------------

| Метод | Описание |
| --- | --- |
| `getClassName()` | Возвращает **название класса**, в котором произошло исключение. |
| `getMethodName()` | Возвращает **название метода**, в котором произошло исключение. |
| `getFileName()` | Возвращает **название файла**, в котором находится этот метод (может быть `null`, если информация недоступна). |
| `getLineNumber()` | Возвращает **номер строки** в исходном файле, где возникло исключение (`-1`, если недоступно). |
| `isNativeMethod()` | Возвращает `true`, если метод является **нативным** (выполняется вне JVM, например, в C/C++). |

* * *

**Пример использования `StackTraceElement`**
--------------------------------------------

```java
public class StackTraceExample {
    public static void main(String[] args) {
        try {
            methodA();
        } catch (Exception e) {
            System.out.println("Исключение: " + e);

            for (StackTraceElement element : e.getStackTrace()) {
                System.out.println("Класс: " + element.getClassName());
                System.out.println("Метод: " + element.getMethodName());
                System.out.println("Файл: " + element.getFileName());
                System.out.println("Строка: " + element.getLineNumber());
                System.out.println("Нативный метод: " + element.isNativeMethod());
                System.out.println("-----");
            }
        }
    }

    public static void methodA() {
        methodB();
    }

    public static void methodB() {
        throw new RuntimeException("Ошибка в methodB");
    }
}
```

* * *

**Пример вывода**
-----------------

```
Исключение: java.lang.RuntimeException: Ошибка в methodB
Класс: StackTraceExample
Метод: methodB
Файл: StackTraceExample.java
Строка: 20
Нативный метод: false
-----
Класс: StackTraceExample
Метод: methodA
Файл: StackTraceExample.java
Строка: 16
Нативный метод: false
-----
Класс: StackTraceExample
Метод: main
Файл: StackTraceExample.java
Строка: 6
Нативный метод: false
-----
```

* * *

**Когда это полезно?**
----------------------

*   **Логирование и отладка** – можно записывать исключения в логи с подробной информацией.
*   **Фильтрация стека вызовов** – можно анализировать только нужные вызовы.
*   **Динамический анализ кода** – можно определять, какой метод вызвал текущий.

* * *

### **Вывод**

Класс `StackTraceElement` помогает получить **класс, метод, файл, номер строки и информацию о нативных методах**, что делает его мощным инструментом для анализа исключений.

## 10. Расскажи про конструкцию try-catch-finally?


### **Конструкция `try-catch-finally` в Java**

Конструкция `try-catch-finally` используется для **обработки исключений** и **гарантированного выполнения кода**, даже если исключение произошло.

* * *

**1\. Основной синтаксис**
--------------------------

```java
try {
    // Код, который может вызвать исключение
} catch (ExceptionType e) {
    // Обработка исключения
} finally {
    // Код, который выполнится в любом случае
}
```

*   **`try`** – блок, в котором может возникнуть исключение.
*   **`catch`** – блок, в котором обрабатывается исключение (`ExceptionType` – конкретный тип исключения).
*   **`finally`** – блок, который **выполняется всегда**, независимо от того, было исключение или нет.

* * *

**2\. Простой пример `try-catch-finally`**
------------------------------------------

```java
public class TryCatchFinallyExample {
    public static void main(String[] args) {
        try {
            int result = 10 / 0; // Деление на ноль вызывает ArithmeticException
            System.out.println("Результат: " + result);
        } catch (ArithmeticException e) {
            System.out.println("Ошибка: " + e.getMessage());
        } finally {
            System.out.println("Этот блок выполнится всегда!");
        }
    }
}
```

### **Вывод в консоль:**

```
Ошибка: / by zero
Этот блок выполнится всегда!
```

**Объяснение:**

*   В `try` происходит исключение (`10 / 0`).
*   В `catch` оно перехватывается.
*   `finally` выполняется **в любом случае**.

* * *

**3\. Когда выполняется `finally`?**
------------------------------------

Блок `finally` **выполняется всегда**, за исключением следующих случаев:

1.  Если в `try` или `catch` вызывается `System.exit(0)`.
2.  Если JVM **аварийно завершается** (например, из-за ошибки в нативном коде).
3.  Если поток (`Thread`) принудительно завершается (`stop()` – но он устарел).

**Пример с `return`:**

```java
public class FinallyExample {
    public static void main(String[] args) {
        System.out.println(testMethod());
    }

    public static String testMethod() {
        try {
            return "Возвращаем из try";
        } catch (Exception e) {
            return "Возвращаем из catch";
        } finally {
            System.out.println("Блок finally выполняется перед return!");
        }
    }
}
```

### **Вывод:**

```
Блок finally выполняется перед return!
Возвращаем из try
```

**Важно!** `finally` выполнится **до того**, как `return` отдаст значение.

* * *

**4\. Можно ли использовать `try-finally` без `catch`?**
--------------------------------------------------------

Да, если нужно **гарантированно выполнить код после `try`**, но не обрабатывать исключение.

```java
public class TryFinallyExample {
    public static void main(String[] args) {
        try {
            System.out.println("Начало работы");
            throw new RuntimeException("Ошибка!");
        } finally {
            System.out.println("Этот блок выполняется всегда!");
        }
    }
}
```

### **Вывод:**

```
Начало работы
Этот блок выполняется всегда!
Exception in thread "main" java.lang.RuntimeException: Ошибка!
```

Исключение не перехвачено (`catch` отсутствует), но `finally` **всё равно отработал**.

* * *

**5\. Обработка нескольких исключений (`multi-catch`)**
-------------------------------------------------------

Можно обрабатывать **несколько исключений в одном `catch`**:

```java
try {
    int[] arr = new int[5];
    arr[10] = 100; // Ошибка выхода за границы массива
} catch (ArithmeticException | ArrayIndexOutOfBoundsException e) {
    System.out.println("Ошибка: " + e.getClass().getSimpleName());
}
```

### **Вывод:**

```
Ошибка: ArrayIndexOutOfBoundsException
```

**Важно:** В `multi-catch` нельзя ловить исключения с отношением **"родитель-потомок"**.

* * *

**6\. Заключение**
------------------

*   **`try`** – блок, где может возникнуть исключение.
*   **`catch`** – ловит исключение и обрабатывает его.
*   **`finally`** – **выполняется всегда**, даже если исключения не было.
*   `try-finally` без `catch` используется для **гарантированного выполнения кода**.
*   `multi-catch` помогает **обрабатывать несколько исключений в одном блоке**.

Использование `finally` полезно для **закрытия ресурсов** (например, потоков, соединений с БД), если не используется `try-with-resources`.

## 11. Что такое try-with-resources? Как работает эта конструкция?


**Try-with-resources в Java**
-----------------------------

`try-with-resources` – это конструкция, которая автоматически **закрывает ресурсы** после использования. Она была добавлена в **Java 7** и работает с классами, реализующими интерфейс `AutoCloseable`.

* * *

**Как работает try-with-resources?**
------------------------------------

Обычно, если мы используем ресурсы (например, файлы, потоки), их **нужно закрывать вручную** в `finally`:

### **До Java 7 (без try-with-resources)**

```java
import java.io.*;

public class OldTryExample {
    public static void main(String[] args) {
        BufferedReader reader = null;
        try {
            reader = new BufferedReader(new FileReader("file.txt"));
            System.out.println(reader.readLine());
        } catch (IOException e) {
            System.out.println("Ошибка: " + e.getMessage());
        } finally {
            try {
                if (reader != null) {
                    reader.close(); // Закрытие вручную
                }
            } catch (IOException e) {
                System.out.println("Ошибка при закрытии файла");
            }
        }
    }
}
```

### **Проблемы подхода:**

*   Много **шаблонного кода** (`null`\-проверки, закрытие `finally`).
*   Возможны ошибки **утечки ресурсов** (если забыли закрыть ресурс).

* * *

**Try-with-resources (начиная с Java 7)**
-----------------------------------------

```java
import java.io.*;

public class TryWithResourcesExample {
    public static void main(String[] args) {
        try (BufferedReader reader = new BufferedReader(new FileReader("file.txt"))) {
            System.out.println(reader.readLine());
        } catch (IOException e) {
            System.out.println("Ошибка: " + e.getMessage());
        }
    }
}
```

### **Преимущества:**

✅ **Ресурсы закрываются автоматически** после выхода из `try`.  
✅ **Нет необходимости в `finally`**.  
✅ Код **чистый и лаконичный**.

* * *

**Как это работает внутри?**
----------------------------

*   Когда блок `try` завершается (нормально или из-за исключения), Java автоматически вызывает метод `close()` у всех ресурсов в **обратном порядке**.
*   Закрываемые ресурсы **должны реализовывать интерфейс** `AutoCloseable` или `Closeable`.

```java
public interface AutoCloseable {
    void close() throws Exception;
}
```

* * *

**Пример с несколькими ресурсами**
----------------------------------

Если в `try` объявлено несколько ресурсов, они закрываются в **обратном порядке**.

```java
import java.io.*;

public class MultipleResourcesExample {
    public static void main(String[] args) {
        try (
            FileInputStream file1 = new FileInputStream("file1.txt");
            FileInputStream file2 = new FileInputStream("file2.txt")
        ) {
            System.out.println("Читаем файлы...");
        } catch (IOException e) {
            System.out.println("Ошибка: " + e.getMessage());
        }
    }
}
```

### **Порядок закрытия ресурсов:**

1️⃣ `file2.close()`  
2️⃣ `file1.close()`

* * *

**Работа с собственными классами**
----------------------------------

Можно использовать **свои ресурсы**, если класс реализует `AutoCloseable`:

```java
class MyResource implements AutoCloseable {
    @Override
    public void close() {
        System.out.println("Ресурс закрыт!");
    }

    void use() {
        System.out.println("Используем ресурс");
    }
}

public class CustomResourceExample {
    public static void main(String[] args) {
        try (MyResource resource = new MyResource()) {
            resource.use();
        }
    }
}
```

### **Вывод:**

```
Используем ресурс
Ресурс закрыт!
```

* * *

**Подавленные исключения (`getSuppressed()`)**
----------------------------------------------

Если в `try` возникает исключение, а затем в `close()` ресурса **тоже выбрасывается исключение**, **второе исключение подавляется**, но его можно получить через `getSuppressed()`.

```java
class FaultyResource implements AutoCloseable {
    @Override
    public void close() throws Exception {
        throw new Exception("Ошибка при закрытии ресурса");
    }
}

public class SuppressedExample {
    public static void main(String[] args) {
        try (FaultyResource res = new FaultyResource()) {
            throw new Exception("Основное исключение в try");
        } catch (Exception e) {
            System.out.println("Основное исключение: " + e.getMessage());
            for (Throwable suppressed : e.getSuppressed()) {
                System.out.println("Подавленное исключение: " + suppressed.getMessage());
            }
        }
    }
}
```

### **Вывод:**

```
Основное исключение: Основное исключение в try
Подавленное исключение: Ошибка при закрытии ресурса
```

* * *

**Вывод**
---------

*   **`try-with-resources` автоматически закрывает ресурсы**, избавляя от необходимости писать `finally`.
*   Работает **с объектами, реализующими `AutoCloseable`**.
*   Упрощает код, **предотвращает утечки ресурсов**.
*   Если в `close()` происходит исключение, оно **подавляется**, но доступно через `getSuppressed()`.

Используйте `try-with-resources` всегда, когда работаете с **файлами, потоками, базами данных, сетевыми соединениями и другими ресурсами**! 🚀

## 12. Расскажи, как правильно ловить исключения? Иерархия catch блоков


**Как правильно ловить исключения в Java?**
===========================================

В Java исключения нужно ловить **грамотно**, чтобы избежать **избыточного кода, утечек ресурсов и скрытых ошибок**.

* * *

**1\. Основные правила обработки исключений**
---------------------------------------------

### ✅ **Ловить только те исключения, которые можно обработать**

❌ **Плохо:** Ловить `Exception` или `Throwable`, не анализируя ситуацию.  
✅ **Хорошо:** Ловить только те исключения, которые можно обработать.

```java
try {
    int result = 10 / 0;
} catch (ArithmeticException e) { // Ловим конкретную ошибку
    System.out.println("Ошибка деления на ноль: " + e.getMessage());
}
```

* * *

**2\. Иерархия catch-блоков**
-----------------------------

В Java исключения имеют **иерархию**, где `Throwable` — самый общий тип:

```
Throwable
 ├── Exception
 │   ├── IOException
 │   ├── SQLException
 │   ├── RuntimeException
 │       ├── ArithmeticException
 │       ├── NullPointerException
 ├── Error
     ├── OutOfMemoryError
     ├── StackOverflowError
```

*   **`Error`** — критические ошибки JVM (НЕ ловим!).
*   **`Exception`** — обычные исключения, которые можно обработать.
*   **`RuntimeException`** — непроверяемые исключения (например, `NullPointerException`).

### **❌ Неправильный порядок catch-блоков**

```java
try {
    int result = 10 / 0;
} catch (Exception e) { // Перехватывает ВСЕ исключения
    System.out.println("Общая ошибка");
} catch (ArithmeticException e) { // Не сработает! (недостижимый код)
    System.out.println("Ошибка деления на ноль");
}
```

**Ошибка компиляции**: `ArithmeticException` наследуется от `Exception`, поэтому этот `catch` **никогда не выполнится**.

* * *

### **✅ Правильный порядок catch-блоков**

```java
try {
    int result = 10 / 0;
} catch (ArithmeticException e) { // Специфичное исключение – первым!
    System.out.println("Ошибка деления на ноль");
} catch (Exception e) { // Более общее исключение – ниже
    System.out.println("Общая ошибка");
}
```

### **Вывод:**

```
Ошибка деления на ноль
```

*   **Сначала** ловим **более специфичные исключения**.
*   **Общие исключения (`Exception`) — в самом конце!**

* * *

**3\. Ловля нескольких исключений (multi-catch)**
-------------------------------------------------

С **Java 7** можно ловить несколько исключений в одном `catch`, используя `|`:

```java
try {
    int[] arr = new int[5];
    arr[10] = 100; // Ошибка выхода за границы массива
} catch (ArithmeticException | ArrayIndexOutOfBoundsException e) {
    System.out.println("Ошибка: " + e.getClass().getSimpleName());
}
```

### **Вывод:**

```
Ошибка: ArrayIndexOutOfBoundsException
```

**Важно:** Исключения **не должны быть в отношении родитель-потомок**, иначе будет ошибка компиляции!

```java
// Ошибка! Нельзя ловить Exception и его подкласс RuntimeException в одном блоке
catch (Exception | RuntimeException e) { ... }
```

* * *

**4\. Использование `finally`**
-------------------------------

Блок `finally` **выполняется всегда** (даже если исключение не произошло):

```java
try {
    int result = 10 / 0;
} catch (ArithmeticException e) {
    System.out.println("Ошибка деления");
} finally {
    System.out.println("Этот блок выполнится всегда!");
}
```

### **Вывод:**

```
Ошибка деления
Этот блок выполнится всегда!
```

**Когда полезен `finally`?**

*   Закрытие файлов, потоков (`BufferedReader.close()`)
*   Освобождение соединений с БД
*   Очистка временных данных

* * *

**5\. Перехват и повторное выбрасывание (`throw`)**
---------------------------------------------------

Иногда исключение нужно **перехватить и пробросить дальше**:

```java
public void process() throws IOException {
    try {
        throw new IOException("Ошибка ввода-вывода");
    } catch (IOException e) {
        System.out.println("Логируем ошибку: " + e.getMessage());
        throw e; // Пробрасываем дальше
    }
}
```

Это полезно, когда **нужно добавить логику** перед передачей исключения дальше.

* * *

**6\. Использование `try-with-resources` (Java 7+)**
----------------------------------------------------

Для **автоматического закрытия ресурсов** используйте `try-with-resources`:

```java
try (BufferedReader reader = new BufferedReader(new FileReader("file.txt"))) {
    System.out.println(reader.readLine());
} catch (IOException e) {
    System.out.println("Ошибка: " + e.getMessage());
}
```

**Преимущества:** ✅ Не нужно `finally` для закрытия ресурсов  
✅ Код чище и надежнее

* * *

**7\. Когда НЕ стоит ловить исключения?**
-----------------------------------------

❌ **Не стоит ловить `Error` (`OutOfMemoryError`, `StackOverflowError`)**  
❌ **Не стоит подавлять исключения (`catch (Exception e) {}` без обработки)**  
❌ **Не стоит просто печатать `e.printStackTrace()` без реакции**

* * *

**Вывод**
---------

1.  **Ловите только нужные исключения** – не перехватывайте `Exception` без необходимости.
2.  **Следите за порядком `catch`\-блоков** – сначала **специфичные**, потом **общие**.
3.  **Используйте `multi-catch`** (Java 7+), если исключения **не связаны**.
4.  **Используйте `finally`** для закрытия ресурсов (или `try-with-resources`).
5.  **Не подавляйте исключения!** Обрабатывайте их корректно.

Следуя этим правилам, код будет **стабильным, читаемым и надежным**! 🚀

## 13. Можно ли в одном catch обработать несколько исключений?


Да, начиная с **Java 7**, можно в одном `catch`\-блоке обработать **несколько исключений**, используя оператор **`|` (pipe)**. Это называется **multi-catch**.

* * *

**Как работает multi-catch?**
-----------------------------

Если несколько исключений требуют **одинаковой обработки**, их можно объединить в **один catch-блок**:

```java
try {
    int[] numbers = new int[5];
    numbers[10] = 100; // Ошибка выхода за границы массива
} catch (ArithmeticException | ArrayIndexOutOfBoundsException e) {
    System.out.println("Ошибка: " + e.getClass().getSimpleName());
}
```

### **Вывод:**

```
Ошибка: ArrayIndexOutOfBoundsException
```

* * *

**Правила multi-catch**
-----------------------

1.  ✅ **Можно объединять только исключения, не находящиеся в одной иерархии**.
2.  ❌ **Нельзя ловить родительский и дочерний класс в одном multi-catch**.

### **❌ Ошибка: Исключения в одной иерархии**

```java
try {
    throw new RuntimeException();
} catch (RuntimeException | Exception e) { // Ошибка компиляции!
    System.out.println("Ошибка");
}
```

❌ **Почему ошибка?**  
`RuntimeException` уже **поймается через `Exception`**, так что `RuntimeException | Exception` не имеет смысла.

* * *

**Когда использовать multi-catch?**
-----------------------------------

✅ Если исключения **не связаны между собой** и требуют одинаковой обработки.  
✅ Если нужно **сократить дублирование кода**.

### **Пример с файлами**

```java
import java.io.*;

public class MultiCatchExample {
    public static void main(String[] args) {
        try (BufferedReader reader = new BufferedReader(new FileReader("file.txt"))) {
            System.out.println(reader.readLine());
        } catch (FileNotFoundException | EOFException e) { 
            System.out.println("Файл не найден или пуст");
        } catch (IOException e) { 
            System.out.println("Ошибка чтения файла");
        }
    }
}
```

* * *

**Вывод**
---------

*   **Multi-catch упрощает код** и убирает дублирование.
*   Работает только с **разными исключениями**, не находящимися в одной иерархии.
*   Если требуется **разная обработка**, лучше использовать **отдельные `catch`\-блоки**.

Используйте multi-catch, когда исключения **логически связаны** и требуют **одинаковой обработки**! 🚀